# Summary
- 자바에는 close()를 통해 닫아줘야 하는 자원들이 많다. 전통적으로는 try-finally를 통해 자원의 닫힘을 보장했다.
- try-finally를 사용하면 try 구문에서 예외가 발생해도 finally 구문은 반드시 실행된다는 이점이 있다. 따라서 자원이 반드시 닫힌다.
- 그런데, finally 구문에서도 예외가 발생하면 어떨까?
  - finally 구문에서 발생한 예외가 try 구문에서 발생한 모든 예외를 덮어버린다.
  - 결과적으로, 디버깅이 굉장히 어렵게 된다. 처음 발생한 에러를 찾을 수가 없게 되기 때문이다

- try-with-resource를 사용하면 처음 발생한 예외가 기록되고 그 다음으로 발생한 에러들 역시 순차적으로 출력된다.
- 결과적으로 try-finally보다 훨씬 디버깅에 유리하다. 
- try-with-resource는 구현한 close() 메서드를 반드시 실행시키기 때문에 자원의 닫힘 역시 보장한다.
- 따라서, 예외 없이 try-finally 보다 try-with-resource를 사용하는게 좋다.
---
### try-finally 의 문제점
```cs
public class Sample {

   public void function(){
        System.out.println("기능 1");
        throw new IllegalArgumentException();
    }

    public void close() {
        System.out.println("종료합니다.");
        throw new IllegalStateException();
    }
}
```

- 위와 같은 예제 클래스를 만들었다고 해보자. 첫 번째 기능과 두 번째 기능, close()는 모두 예외를 발생시키는 메서드이다.
- 이 메서드를 아래와 같이 사용한다고 해보자.

```cs
    public static void main(String[] args) {
        Sample sample = new Sample();
        try{
            sample.function();
        }finally {
            sample.close();
        }
    }
```
- 이 main 메서드를 실행하면 마지막 예외가 위의 두 예외를 덮어버린다. 콘솔에 출력되는 결과를 살펴보면 다음과 같다.
```
기능 1
종료합니다.
Exception in thread "main" java.lang.IllegalStateException
	at Sample.close(Sample.java:15)
	at Main.main(Main.java:14)
```
---

###  try-with-resource의 사용
- 다행히도 자바 7부터는 try-with-resource를 지원해 위와 같은 문제를 방지할 수 있다.
- try-with-resource를 사용하기 위해선 사용되는 자원이 AutoCloseable 인터페이스를 구현한 상태여야 한다.
  - AutoCloaseable 인터페이스는 close()만을 담고있는 functional 인터페이스다.
  - 위의 Sample 예시를 해당 인터페이스를 구현한 인터페이스로 바꾸면 아래와 같다.
```cs
public class Sample implements AutoCloseable{

    public void function(){
        System.out.println("기능 1");
        throw new IllegalArgumentException();
    }

    @Override
    public void close() {
        System.out.println("종료합니다.");
        throw new IllegalStateException();
    }
}
```
- 위의 try-finally문은 어떻게 바뀔까. 아래와 같다.
```cs
    public static void main(String[] args) {
        try (Sample sample = new Sample()) {
            sample.function();
        }
    }
```
- try-finally에 비해 훨씬 심플해졌다. 이는 잠시 후에 살펴볼 여러 자원을 사용하는 경우에 더욱 두드러진다.
- 그럼 위의 메인 메서드를 실행한 결과는 어떨까?
```
기능 1
종료합니다.
Exception in thread "main" java.lang.IllegalArgumentException
	at Sample.function(Sample.java:5)
	at Main.main(Main.java:10)
	Suppressed: java.lang.IllegalStateException
		at Sample.close(Sample.java:11)
		at Main.main(Main.java:9)
```
- try-finally와 달리, 먼저 function()의 예외가 콘솔에 찍힌다. 그리고 Suppressed가 달린 채로 close()의 예외가 찍힌다.
- 우리는 이를 통해 훨씬 쉽게 디버깅을 진행할 수 있다.
---
### 여러 자원을 사용할 때
- close()해줘야 할 자원이 두 개인 경우를 try-finally로 작성해보자.
	- 예시에는 SecondSample 이라는 클래스를 만들어 사용했다. 클래스의 내용은 Sample과 같다. 
```cs
    public static void main(String[] args) {
        Sample sample = new Sample();
        try {
            SecondSample secondSample = new SecondSample();
            sample.function();
            try {
                secondSample.function();
            } finally {
                secondSample.close();
            }
        } finally {
            sample.close();
        }
    }
```
- 보기에도 어렵고 예외의 출력도 제대로 되지 않는다. 위에서와 마찬가지로 출력되는 예외는 마지막 sample.close()가 덮는다. 
- 그럼 이를 try-with-resource로 작성하면 어떨까.
```cs
    public static void main(String[] args) {
        try (Sample sample = new Sample();
             SecondSample secondSample = new SecondSample()) {
            sample.function();
            secondSample.function();
        }
    }
```
- 보기에 훨씬 편해졌다. try-with-resource문은 try 내부에 동시에 여러 자원을 정의할 수 있다!
- 당연하게도, 실행되는 모든 메서드들의 에러를 콘솔에서 확인할 수 있다. `sample.funtion(), sample.close(), secondSample.close()`
	- secondSample.function()은 sample.function에서 예외가 발생하기 때문에 실행되지 않는다.  
